2019-07-29 13:41:15,618 [ERROR]  Unable to start server
Traceback (most recent call last):
  File "uvloop/loop.pyx", line 1112, in uvloop.loop.Loop._create_server
  File "uvloop/handles/streamserver.pyx", line 58, in uvloop.loop.UVStreamServer.listen
  File "uvloop/handles/streamserver.pyx", line 95, in uvloop.loop.UVStreamServer._fatal_error
OSError: [Errno 98] Address already in use

During handling of the above exception, another exception occurred:

Traceback (most recent call last):
  File "/home/bartek/.local/lib/python3.6/site-packages/sanic/server.py", line 745, in serve
    http_server = loop.run_until_complete(server_coroutine)
  File "uvloop/loop.pyx", line 1451, in uvloop.loop.Loop.run_until_complete
  File "uvloop/loop.pyx", line 1684, in create_server
  File "uvloop/loop.pyx", line 1116, in uvloop.loop.Loop._create_server
OSError: [Errno 98] error while attempting to bind on address ('0.0.0.0', 5500): address already in use
2019-07-29 13:42:53,684 [ERROR]  Exception occurred while handling uri: 'http://localhost:5500/'
Traceback (most recent call last):
  File "/home/bartek/.local/lib/python3.6/site-packages/sanic/app.py", line 893, in handle_request
    handler, args, kwargs, uri = self.router.get(request)
  File "/home/bartek/.local/lib/python3.6/site-packages/sanic/router.py", line 407, in get
    return self._get(request.path, request.method, "")
  File "/home/bartek/.local/lib/python3.6/site-packages/sanic/router.py", line 469, in _get
    raise NotFound("Requested URL {} not found".format(url))
sanic.exceptions.NotFound: Requested URL / not found
2019-07-29 13:42:57,715 [ERROR]  Exception occurred while handling uri: 'http://localhost:5500/'
Traceback (most recent call last):
  File "/home/bartek/.local/lib/python3.6/site-packages/sanic/app.py", line 893, in handle_request
    handler, args, kwargs, uri = self.router.get(request)
  File "/home/bartek/.local/lib/python3.6/site-packages/sanic/router.py", line 407, in get
    return self._get(request.path, request.method, "")
  File "/home/bartek/.local/lib/python3.6/site-packages/sanic/router.py", line 469, in _get
    raise NotFound("Requested URL {} not found".format(url))
sanic.exceptions.NotFound: Requested URL / not found
2019-07-29 13:43:42,472 [ERROR]  Exception occurred while handling uri: 'http://localhost:5500/'
Traceback (most recent call last):
  File "/home/bartek/.local/lib/python3.6/site-packages/sanic/app.py", line 893, in handle_request
    handler, args, kwargs, uri = self.router.get(request)
  File "/home/bartek/.local/lib/python3.6/site-packages/sanic/router.py", line 407, in get
    return self._get(request.path, request.method, "")
  File "/home/bartek/.local/lib/python3.6/site-packages/sanic/router.py", line 469, in _get
    raise NotFound("Requested URL {} not found".format(url))
sanic.exceptions.NotFound: Requested URL / not found
2019-07-29 13:48:07,624 [ERROR]  Experienced exception while trying to serve
Traceback (most recent call last):
  File "/home/bartek/.local/lib/python3.6/site-packages/sanic/app.py", line 1096, in run
    serve(**server_settings)
  File "/home/bartek/.local/lib/python3.6/site-packages/sanic/server.py", line 742, in serve
    trigger_events(before_start, loop)
  File "/home/bartek/.local/lib/python3.6/site-packages/sanic/server.py", line 604, in trigger_events
    loop.run_until_complete(result)
  File "uvloop/loop.pyx", line 1445, in uvloop.loop.Loop.run_until_complete
  File "uvloop/loop.pyx", line 1438, in uvloop.loop.Loop.run_until_complete
  File "uvloop/loop.pyx", line 1347, in uvloop.loop.Loop.run_forever
  File "uvloop/loop.pyx", line 487, in uvloop.loop.Loop._run
  File "uvloop/loop.pyx", line 404, in uvloop.loop.Loop._on_idle
  File "uvloop/cbhandles.pyx", line 66, in uvloop.loop.Handle._run
  File "/home/bartek/.local/lib/python3.6/site-packages/rasa/core/run.py", line 192, in load_agent_on_start
    _interpreter = NaturalLanguageInterpreter.create(nlu_model, endpoints.nlu)
  File "/home/bartek/.local/lib/python3.6/site-packages/rasa/core/interpreter.py", line 53, in create
    return RasaNLUInterpreter(model_directory=obj)
  File "/home/bartek/.local/lib/python3.6/site-packages/rasa/core/interpreter.py", line 247, in __init__
    self._load_interpreter()
  File "/home/bartek/.local/lib/python3.6/site-packages/rasa/core/interpreter.py", line 267, in _load_interpreter
    self.interpreter = Interpreter.load(self.model_directory)
  File "/home/bartek/.local/lib/python3.6/site-packages/rasa/nlu/model.py", line 301, in load
    return Interpreter.create(model_metadata, component_builder, skip_validation)
  File "/home/bartek/.local/lib/python3.6/site-packages/rasa/nlu/model.py", line 328, in create
    component_meta, model_metadata.model_dir, model_metadata, **context
  File "/home/bartek/.local/lib/python3.6/site-packages/rasa/nlu/components.py", line 433, in load_component
    component_meta, model_dir, model_metadata, cached_component, **context
  File "/home/bartek/.local/lib/python3.6/site-packages/rasa/nlu/registry.py", line 181, in load_component_by_meta
    component_meta, model_dir, metadata, cached_component, **kwargs
  File "/home/bartek/.local/lib/python3.6/site-packages/rasa/nlu/classifiers/embedding_intent_classifier.py", line 697, in load
    saver = tf.train.import_meta_graph(checkpoint + ".meta")
  File "/home/bartek/.local/lib/python3.6/site-packages/tensorflow/python/training/saver.py", line 1435, in import_meta_graph
    meta_graph_or_file, clear_devices, import_scope, **kwargs)[0]
  File "/home/bartek/.local/lib/python3.6/site-packages/tensorflow/python/training/saver.py", line 1457, in _import_meta_graph_with_return_elements
    **kwargs))
  File "/home/bartek/.local/lib/python3.6/site-packages/tensorflow/python/framework/meta_graph.py", line 806, in import_scoped_meta_graph_with_return_elements
    return_elements=return_elements)
  File "/home/bartek/.local/lib/python3.6/site-packages/tensorflow/python/util/deprecation.py", line 507, in new_func
    return func(*args, **kwargs)
  File "/home/bartek/.local/lib/python3.6/site-packages/tensorflow/python/framework/importer.py", line 399, in import_graph_def
    _RemoveDefaultAttrs(op_dict, producer_op_list, graph_def)
  File "/home/bartek/.local/lib/python3.6/site-packages/tensorflow/python/framework/importer.py", line 163, in _RemoveDefaultAttrs
    for key in list(node.attr):
  File "/home/bartek/.local/lib/python3.6/site-packages/socketio/client.py", line 25, in signal_handler
    return original_signal_handler(sig, frame)
  File "/home/bartek/.local/lib/python3.6/site-packages/engineio/client.py", line 41, in signal_handler
    return original_signal_handler(sig, frame)
KeyboardInterrupt
2019-07-29 15:30:56,807 [ERROR]  Unable to start server
Traceback (most recent call last):
  File "uvloop/loop.pyx", line 1112, in uvloop.loop.Loop._create_server
  File "uvloop/handles/streamserver.pyx", line 58, in uvloop.loop.UVStreamServer.listen
  File "uvloop/handles/streamserver.pyx", line 95, in uvloop.loop.UVStreamServer._fatal_error
OSError: [Errno 98] Address already in use

During handling of the above exception, another exception occurred:

Traceback (most recent call last):
  File "/home/bartek/.local/lib/python3.6/site-packages/sanic/server.py", line 745, in serve
    http_server = loop.run_until_complete(server_coroutine)
  File "uvloop/loop.pyx", line 1451, in uvloop.loop.Loop.run_until_complete
  File "uvloop/loop.pyx", line 1684, in create_server
  File "uvloop/loop.pyx", line 1116, in uvloop.loop.Loop._create_server
OSError: [Errno 98] error while attempting to bind on address ('0.0.0.0', 5055): address already in use
2019-07-29 15:34:45,469 [ERROR]  Unable to start server
Traceback (most recent call last):
  File "uvloop/loop.pyx", line 1112, in uvloop.loop.Loop._create_server
  File "uvloop/handles/streamserver.pyx", line 58, in uvloop.loop.UVStreamServer.listen
  File "uvloop/handles/streamserver.pyx", line 95, in uvloop.loop.UVStreamServer._fatal_error
OSError: [Errno 98] Address already in use

During handling of the above exception, another exception occurred:

Traceback (most recent call last):
  File "/home/bartek/Enviroments/simple_rasa_bot/lib/python3.6/site-packages/sanic/server.py", line 745, in serve
    http_server = loop.run_until_complete(server_coroutine)
  File "uvloop/loop.pyx", line 1451, in uvloop.loop.Loop.run_until_complete
  File "uvloop/loop.pyx", line 1684, in create_server
  File "uvloop/loop.pyx", line 1116, in uvloop.loop.Loop._create_server
OSError: [Errno 98] error while attempting to bind on address ('0.0.0.0', 5055): address already in use
2019-07-29 15:35:24,677 [ERROR]  Experienced exception while trying to serve
Traceback (most recent call last):
  File "/home/bartek/Enviroments/simple_rasa_bot/lib/python3.6/site-packages/sanic/app.py", line 1096, in run
    serve(**server_settings)
  File "/home/bartek/Enviroments/simple_rasa_bot/lib/python3.6/site-packages/sanic/server.py", line 742, in serve
    trigger_events(before_start, loop)
  File "/home/bartek/Enviroments/simple_rasa_bot/lib/python3.6/site-packages/sanic/server.py", line 604, in trigger_events
    loop.run_until_complete(result)
  File "uvloop/loop.pyx", line 1445, in uvloop.loop.Loop.run_until_complete
  File "uvloop/loop.pyx", line 1438, in uvloop.loop.Loop.run_until_complete
  File "uvloop/loop.pyx", line 1347, in uvloop.loop.Loop.run_forever
  File "uvloop/loop.pyx", line 487, in uvloop.loop.Loop._run
  File "uvloop/loop.pyx", line 404, in uvloop.loop.Loop._on_idle
  File "uvloop/cbhandles.pyx", line 66, in uvloop.loop.Handle._run
  File "/home/bartek/Enviroments/simple_rasa_bot/lib/python3.6/site-packages/rasa/core/run.py", line 211, in load_agent_on_start
    action_endpoint=endpoints.action,
  File "/home/bartek/Enviroments/simple_rasa_bot/lib/python3.6/site-packages/rasa/core/agent.py", line 262, in load_agent
    remote_storage=remote_storage,
  File "/home/bartek/Enviroments/simple_rasa_bot/lib/python3.6/site-packages/rasa/core/agent.py", line 892, in load_local_model
    remote_storage=remote_storage,
  File "/home/bartek/Enviroments/simple_rasa_bot/lib/python3.6/site-packages/rasa/core/agent.py", line 378, in load
    ensemble = PolicyEnsemble.load(core_model) if core_model else None
  File "/home/bartek/Enviroments/simple_rasa_bot/lib/python3.6/site-packages/rasa/core/policies/ensemble.py", line 232, in load
    policy = policy_cls.load(policy_path)
  File "/home/bartek/Enviroments/simple_rasa_bot/lib/python3.6/site-packages/rasa/core/policies/keras_policy.py", line 320, in load
    model = load_model(model_file)
  File "/home/bartek/Enviroments/simple_rasa_bot/lib/python3.6/site-packages/tensorflow/python/keras/engine/saving.py", line 237, in load_model
    load_weights_from_hdf5_group(f['model_weights'], model.layers)
  File "/home/bartek/Enviroments/simple_rasa_bot/lib/python3.6/site-packages/tensorflow/python/keras/engine/saving.py", line 820, in load_weights_from_hdf5_group
    K.batch_set_value(weight_value_tuples)
  File "/home/bartek/Enviroments/simple_rasa_bot/lib/python3.6/site-packages/tensorflow/python/keras/backend.py", line 2880, in batch_set_value
    get_session().run(assign_ops, feed_dict=feed_dict)
  File "/home/bartek/Enviroments/simple_rasa_bot/lib/python3.6/site-packages/tensorflow/python/keras/backend.py", line 482, in get_session
    _initialize_variables(session)
  File "/home/bartek/Enviroments/simple_rasa_bot/lib/python3.6/site-packages/tensorflow/python/keras/backend.py", line 758, in _initialize_variables
    [variables_module.is_variable_initialized(v) for v in candidate_vars])
  File "/home/bartek/Enviroments/simple_rasa_bot/lib/python3.6/site-packages/tensorflow/python/keras/backend.py", line 758, in <listcomp>
    [variables_module.is_variable_initialized(v) for v in candidate_vars])
  File "/home/bartek/Enviroments/simple_rasa_bot/lib/python3.6/site-packages/tensorflow/python/util/tf_should_use.py", line 193, in wrapped
    return _add_should_use_warning(fn(*args, **kwargs))
  File "/home/bartek/Enviroments/simple_rasa_bot/lib/python3.6/site-packages/tensorflow/python/ops/variables.py", line 2924, in is_variable_initialized
    return state_ops.is_variable_initialized(variable)
  File "/home/bartek/Enviroments/simple_rasa_bot/lib/python3.6/site-packages/tensorflow/python/ops/state_ops.py", line 133, in is_variable_initialized
    return ref.is_initialized(name=name)
  File "/home/bartek/Enviroments/simple_rasa_bot/lib/python3.6/site-packages/tensorflow/python/ops/resource_variable_ops.py", line 833, in is_initialized
    return gen_resource_variable_ops.var_is_initialized_op(self.handle, name)
  File "/home/bartek/Enviroments/simple_rasa_bot/lib/python3.6/site-packages/tensorflow/python/ops/gen_resource_variable_ops.py", line 1334, in var_is_initialized_op
    "VarIsInitializedOp", resource=resource, name=name)
  File "/home/bartek/Enviroments/simple_rasa_bot/lib/python3.6/site-packages/tensorflow/python/framework/op_def_library.py", line 789, in _apply_op_helper
    return output_structure, op_def.is_stateful, op
  File "/home/bartek/Enviroments/simple_rasa_bot/lib/python3.6/site-packages/tensorflow/python/framework/ops.py", line 6100, in __exit__
    self._g_manager.__exit__(type_arg, value_arg, traceback_arg)
  File "/usr/lib/python3.6/contextlib.py", line 88, in __exit__
    next(self.gen)
  File "/home/bartek/Enviroments/simple_rasa_bot/lib/python3.6/site-packages/tensorflow/python/framework/ops.py", line 5253, in get_controller
    yield g
  File "/usr/lib/python3.6/contextlib.py", line 88, in __exit__
    next(self.gen)
  File "/home/bartek/Enviroments/simple_rasa_bot/lib/python3.6/site-packages/socketio/client.py", line 25, in signal_handler
    return original_signal_handler(sig, frame)
  File "/home/bartek/Enviroments/simple_rasa_bot/lib/python3.6/site-packages/engineio/client.py", line 41, in signal_handler
    return original_signal_handler(sig, frame)
KeyboardInterrupt
2019-07-29 15:36:42,415 [ERROR]  Unable to start server
Traceback (most recent call last):
  File "uvloop/loop.pyx", line 1112, in uvloop.loop.Loop._create_server
  File "uvloop/handles/streamserver.pyx", line 58, in uvloop.loop.UVStreamServer.listen
  File "uvloop/handles/streamserver.pyx", line 95, in uvloop.loop.UVStreamServer._fatal_error
OSError: [Errno 98] Address already in use

During handling of the above exception, another exception occurred:

Traceback (most recent call last):
  File "/home/bartek/Enviroments/simple_rasa_bot/lib/python3.6/site-packages/sanic/server.py", line 745, in serve
    http_server = loop.run_until_complete(server_coroutine)
  File "uvloop/loop.pyx", line 1451, in uvloop.loop.Loop.run_until_complete
  File "uvloop/loop.pyx", line 1684, in create_server
  File "uvloop/loop.pyx", line 1116, in uvloop.loop.Loop._create_server
OSError: [Errno 98] error while attempting to bind on address ('0.0.0.0', 5055): address already in use
2019-07-29 15:37:42,109 [ERROR]  Unable to start server
Traceback (most recent call last):
  File "uvloop/loop.pyx", line 1112, in uvloop.loop.Loop._create_server
  File "uvloop/handles/streamserver.pyx", line 58, in uvloop.loop.UVStreamServer.listen
  File "uvloop/handles/streamserver.pyx", line 95, in uvloop.loop.UVStreamServer._fatal_error
OSError: [Errno 98] Address already in use

During handling of the above exception, another exception occurred:

Traceback (most recent call last):
  File "/home/bartek/Enviroments/simple_rasa_bot/lib/python3.6/site-packages/sanic/server.py", line 745, in serve
    http_server = loop.run_until_complete(server_coroutine)
  File "uvloop/loop.pyx", line 1451, in uvloop.loop.Loop.run_until_complete
  File "uvloop/loop.pyx", line 1684, in create_server
  File "uvloop/loop.pyx", line 1116, in uvloop.loop.Loop._create_server
OSError: [Errno 98] error while attempting to bind on address ('0.0.0.0', 5055): address already in use
2019-07-29 15:39:48,173 [ERROR]  Unable to start server
Traceback (most recent call last):
  File "uvloop/loop.pyx", line 1112, in uvloop.loop.Loop._create_server
  File "uvloop/handles/streamserver.pyx", line 58, in uvloop.loop.UVStreamServer.listen
  File "uvloop/handles/streamserver.pyx", line 95, in uvloop.loop.UVStreamServer._fatal_error
OSError: [Errno 98] Address already in use

During handling of the above exception, another exception occurred:

Traceback (most recent call last):
  File "/home/bartek/Enviroments/simple_rasa_bot/lib/python3.6/site-packages/sanic/server.py", line 745, in serve
    http_server = loop.run_until_complete(server_coroutine)
  File "uvloop/loop.pyx", line 1451, in uvloop.loop.Loop.run_until_complete
  File "uvloop/loop.pyx", line 1684, in create_server
  File "uvloop/loop.pyx", line 1116, in uvloop.loop.Loop._create_server
OSError: [Errno 98] error while attempting to bind on address ('0.0.0.0', 5055): address already in use
2019-07-29 15:42:23,144 [ERROR]  Unable to start server
Traceback (most recent call last):
  File "uvloop/loop.pyx", line 1112, in uvloop.loop.Loop._create_server
  File "uvloop/handles/streamserver.pyx", line 58, in uvloop.loop.UVStreamServer.listen
  File "uvloop/handles/streamserver.pyx", line 95, in uvloop.loop.UVStreamServer._fatal_error
OSError: [Errno 98] Address already in use

During handling of the above exception, another exception occurred:

Traceback (most recent call last):
  File "/home/bartek/Enviroments/simple_rasa_bot/lib/python3.6/site-packages/sanic/server.py", line 745, in serve
    http_server = loop.run_until_complete(server_coroutine)
  File "uvloop/loop.pyx", line 1451, in uvloop.loop.Loop.run_until_complete
  File "uvloop/loop.pyx", line 1684, in create_server
  File "uvloop/loop.pyx", line 1116, in uvloop.loop.Loop._create_server
OSError: [Errno 98] error while attempting to bind on address ('0.0.0.0', 5055): address already in use
2019-07-29 15:51:11,687 [ERROR]  Exception occurred while handling uri: 'http://localhost:5000/'
Traceback (most recent call last):
  File "/home/bartek/Enviroments/simple_rasa_bot/lib/python3.6/site-packages/sanic/app.py", line 893, in handle_request
    handler, args, kwargs, uri = self.router.get(request)
  File "/home/bartek/Enviroments/simple_rasa_bot/lib/python3.6/site-packages/sanic/router.py", line 407, in get
    return self._get(request.path, request.method, "")
  File "/home/bartek/Enviroments/simple_rasa_bot/lib/python3.6/site-packages/sanic/router.py", line 469, in _get
    raise NotFound("Requested URL {} not found".format(url))
sanic.exceptions.NotFound: Requested URL / not found
2019-07-29 16:02:36,746 [ERROR]  Exception occurred while handling uri: 'http://localhost:5000/'
Traceback (most recent call last):
  File "/home/bartek/Enviroments/simple_rasa_bot/lib/python3.6/site-packages/sanic/app.py", line 893, in handle_request
    handler, args, kwargs, uri = self.router.get(request)
  File "/home/bartek/Enviroments/simple_rasa_bot/lib/python3.6/site-packages/sanic/router.py", line 407, in get
    return self._get(request.path, request.method, "")
  File "/home/bartek/Enviroments/simple_rasa_bot/lib/python3.6/site-packages/sanic/router.py", line 469, in _get
    raise NotFound("Requested URL {} not found".format(url))
sanic.exceptions.NotFound: Requested URL / not found
2019-07-29 16:02:37,058 [ERROR]  Exception occurred while handling uri: 'http://localhost:5000/favicon.ico'
Traceback (most recent call last):
  File "/home/bartek/Enviroments/simple_rasa_bot/lib/python3.6/site-packages/sanic/app.py", line 893, in handle_request
    handler, args, kwargs, uri = self.router.get(request)
  File "/home/bartek/Enviroments/simple_rasa_bot/lib/python3.6/site-packages/sanic/router.py", line 407, in get
    return self._get(request.path, request.method, "")
  File "/home/bartek/Enviroments/simple_rasa_bot/lib/python3.6/site-packages/sanic/router.py", line 469, in _get
    raise NotFound("Requested URL {} not found".format(url))
sanic.exceptions.NotFound: Requested URL /favicon.ico not found
2019-07-29 16:12:52,804 [ERROR]  Experienced exception while trying to serve
Traceback (most recent call last):
  File "/home/bartek/Enviroments/simple_rasa_bot/lib/python3.6/site-packages/sanic/app.py", line 1096, in run
    serve(**server_settings)
  File "/home/bartek/Enviroments/simple_rasa_bot/lib/python3.6/site-packages/sanic/server.py", line 742, in serve
    trigger_events(before_start, loop)
  File "/home/bartek/Enviroments/simple_rasa_bot/lib/python3.6/site-packages/sanic/server.py", line 604, in trigger_events
    loop.run_until_complete(result)
  File "uvloop/loop.pyx", line 1445, in uvloop.loop.Loop.run_until_complete
  File "uvloop/loop.pyx", line 1438, in uvloop.loop.Loop.run_until_complete
  File "uvloop/loop.pyx", line 1347, in uvloop.loop.Loop.run_forever
  File "uvloop/loop.pyx", line 487, in uvloop.loop.Loop._run
  File "uvloop/loop.pyx", line 404, in uvloop.loop.Loop._on_idle
  File "uvloop/cbhandles.pyx", line 66, in uvloop.loop.Handle._run
  File "/home/bartek/Enviroments/simple_rasa_bot/lib/python3.6/site-packages/rasa/core/run.py", line 211, in load_agent_on_start
    action_endpoint=endpoints.action,
  File "/home/bartek/Enviroments/simple_rasa_bot/lib/python3.6/site-packages/rasa/core/agent.py", line 262, in load_agent
    remote_storage=remote_storage,
  File "/home/bartek/Enviroments/simple_rasa_bot/lib/python3.6/site-packages/rasa/core/agent.py", line 892, in load_local_model
    remote_storage=remote_storage,
  File "/home/bartek/Enviroments/simple_rasa_bot/lib/python3.6/site-packages/rasa/core/agent.py", line 378, in load
    ensemble = PolicyEnsemble.load(core_model) if core_model else None
  File "/home/bartek/Enviroments/simple_rasa_bot/lib/python3.6/site-packages/rasa/core/policies/ensemble.py", line 232, in load
    policy = policy_cls.load(policy_path)
  File "/home/bartek/Enviroments/simple_rasa_bot/lib/python3.6/site-packages/rasa/core/policies/keras_policy.py", line 320, in load
    model = load_model(model_file)
  File "/home/bartek/Enviroments/simple_rasa_bot/lib/python3.6/site-packages/tensorflow/python/keras/engine/saving.py", line 285, in load_model
    model.optimizer.set_weights(optimizer_weight_values)
  File "/home/bartek/Enviroments/simple_rasa_bot/lib/python3.6/site-packages/tensorflow/python/keras/optimizers.py", line 139, in set_weights
    K.batch_set_value(weight_value_tuples)
  File "/home/bartek/Enviroments/simple_rasa_bot/lib/python3.6/site-packages/tensorflow/python/keras/backend.py", line 2880, in batch_set_value
    get_session().run(assign_ops, feed_dict=feed_dict)
  File "/home/bartek/Enviroments/simple_rasa_bot/lib/python3.6/site-packages/tensorflow/python/client/session.py", line 929, in run
    run_metadata_ptr)
  File "/home/bartek/Enviroments/simple_rasa_bot/lib/python3.6/site-packages/tensorflow/python/client/session.py", line 1152, in _run
    feed_dict_tensor, options, run_metadata)
  File "/home/bartek/Enviroments/simple_rasa_bot/lib/python3.6/site-packages/tensorflow/python/client/session.py", line 1328, in _do_run
    run_metadata)
  File "/home/bartek/Enviroments/simple_rasa_bot/lib/python3.6/site-packages/tensorflow/python/client/session.py", line 1334, in _do_call
    return fn(*args)
  File "/home/bartek/Enviroments/simple_rasa_bot/lib/python3.6/site-packages/tensorflow/python/client/session.py", line 1317, in _run_fn
    self._extend_graph()
  File "/home/bartek/Enviroments/simple_rasa_bot/lib/python3.6/site-packages/tensorflow/python/client/session.py", line 1352, in _extend_graph
    tf_session.ExtendSession(self._session)
  File "/home/bartek/Enviroments/simple_rasa_bot/lib/python3.6/site-packages/socketio/client.py", line 25, in signal_handler
    return original_signal_handler(sig, frame)
  File "/home/bartek/Enviroments/simple_rasa_bot/lib/python3.6/site-packages/engineio/client.py", line 41, in signal_handler
    return original_signal_handler(sig, frame)
KeyboardInterrupt
2019-07-29 16:13:47,496 [ERROR]  Exception occurred while handling uri: 'http://localhost:5000/'
Traceback (most recent call last):
  File "/home/bartek/Enviroments/simple_rasa_bot/lib/python3.6/site-packages/sanic/app.py", line 893, in handle_request
    handler, args, kwargs, uri = self.router.get(request)
  File "/home/bartek/Enviroments/simple_rasa_bot/lib/python3.6/site-packages/sanic/router.py", line 407, in get
    return self._get(request.path, request.method, "")
  File "/home/bartek/Enviroments/simple_rasa_bot/lib/python3.6/site-packages/sanic/router.py", line 469, in _get
    raise NotFound("Requested URL {} not found".format(url))
sanic.exceptions.NotFound: Requested URL / not found
