Rasa process starting
From /home/bartek/.local/lib/python3.6/site-packages/tensorflow/python/training/saver.py:1266: checkpoint_exists (from tensorflow.python.training.checkpoint_management) is deprecated and will be removed in a future version.
Instructions for updating:
Use standard file APIs to check for files with this prefix.
Restoring parameters from models/current/nlu/component_5_EmbeddingIntentClassifier.ckpt
Generating grammar tables from /usr/lib/python3.6/lib2to3/Grammar.txt
Generating grammar tables from /usr/lib/python3.6/lib2to3/PatternGrammar.txt
Scheduler started
/home/bartek/.local/lib/python3.6/site-packages/pykwalify/core.py:99: UnsafeLoaderWarning: 
The default 'Loader' for 'load(stream)' without further arguments can be unsafe.
Use 'load(stream, Loader=ruamel.yaml.Loader)' explicitly if that is OK.
Alternatively include the following in your code:

  import warnings
  warnings.simplefilter('ignore', ruamel.yaml.error.UnsafeLoaderWarning)

In most other cases you should consider using 'safe_load(stream)'
  data = yaml.load(stream)

Rasa process starting
2019-07-12 17:48:03,035 [ERROR]  Exception occurred while handling uri: 'http://4955cb61.ngrok.io/'
Traceback (most recent call last):
  File "/home/bartek/Enviroments/simple_rasa_bot/lib/python3.6/site-packages/sanic/app.py", line 893, in handle_request
    handler, args, kwargs, uri = self.router.get(request)
  File "/home/bartek/Enviroments/simple_rasa_bot/lib/python3.6/site-packages/sanic/router.py", line 407, in get
    return self._get(request.path, request.method, "")
  File "/home/bartek/Enviroments/simple_rasa_bot/lib/python3.6/site-packages/sanic/router.py", line 469, in _get
    raise NotFound("Requested URL {} not found".format(url))
sanic.exceptions.NotFound: Requested URL / not found
2019-07-12 17:55:33,634 [ERROR]  Exception occurred while handling uri: 'http://localhost:5002/'
Traceback (most recent call last):
  File "/home/bartek/Enviroments/simple_rasa_bot/lib/python3.6/site-packages/sanic/app.py", line 893, in handle_request
    handler, args, kwargs, uri = self.router.get(request)
  File "/home/bartek/Enviroments/simple_rasa_bot/lib/python3.6/site-packages/sanic/router.py", line 407, in get
    return self._get(request.path, request.method, "")
  File "/home/bartek/Enviroments/simple_rasa_bot/lib/python3.6/site-packages/sanic/router.py", line 469, in _get
    raise NotFound("Requested URL {} not found".format(url))
sanic.exceptions.NotFound: Requested URL / not found
2019-07-12 17:55:33,727 [ERROR]  Exception occurred while handling uri: 'http://localhost:5002/favicon.ico'
Traceback (most recent call last):
  File "/home/bartek/Enviroments/simple_rasa_bot/lib/python3.6/site-packages/sanic/app.py", line 893, in handle_request
    handler, args, kwargs, uri = self.router.get(request)
  File "/home/bartek/Enviroments/simple_rasa_bot/lib/python3.6/site-packages/sanic/router.py", line 407, in get
    return self._get(request.path, request.method, "")
  File "/home/bartek/Enviroments/simple_rasa_bot/lib/python3.6/site-packages/sanic/router.py", line 469, in _get
    raise NotFound("Requested URL {} not found".format(url))
sanic.exceptions.NotFound: Requested URL /favicon.ico not found
2019-07-15 12:50:20,617 [ERROR]  Unable to start server
Traceback (most recent call last):
  File "uvloop/loop.pyx", line 1112, in uvloop.loop.Loop._create_server
  File "uvloop/handles/streamserver.pyx", line 58, in uvloop.loop.UVStreamServer.listen
  File "uvloop/handles/streamserver.pyx", line 95, in uvloop.loop.UVStreamServer._fatal_error
OSError: [Errno 98] Address already in use

During handling of the above exception, another exception occurred:

Traceback (most recent call last):
  File "/home/bartek/Enviroments/simple_rasa_bot/lib/python3.6/site-packages/sanic/server.py", line 745, in serve
    http_server = loop.run_until_complete(server_coroutine)
  File "uvloop/loop.pyx", line 1451, in uvloop.loop.Loop.run_until_complete
  File "uvloop/loop.pyx", line 1684, in create_server
  File "uvloop/loop.pyx", line 1116, in uvloop.loop.Loop._create_server
OSError: [Errno 98] error while attempting to bind on address ('0.0.0.0', 5005): address already in use
2019-07-15 13:01:15,900 [ERROR]  Unable to start server
Traceback (most recent call last):
  File "uvloop/loop.pyx", line 1112, in uvloop.loop.Loop._create_server
  File "uvloop/handles/streamserver.pyx", line 58, in uvloop.loop.UVStreamServer.listen
  File "uvloop/handles/streamserver.pyx", line 95, in uvloop.loop.UVStreamServer._fatal_error
OSError: [Errno 98] Address already in use

During handling of the above exception, another exception occurred:

Traceback (most recent call last):
  File "/home/bartek/.local/lib/python3.6/site-packages/sanic/server.py", line 745, in serve
    http_server = loop.run_until_complete(server_coroutine)
  File "uvloop/loop.pyx", line 1451, in uvloop.loop.Loop.run_until_complete
  File "uvloop/loop.pyx", line 1684, in create_server
  File "uvloop/loop.pyx", line 1116, in uvloop.loop.Loop._create_server
OSError: [Errno 98] error while attempting to bind on address ('0.0.0.0', 5005): address already in use
2019-07-15 13:01:25,245 [ERROR]  Unable to start server
Traceback (most recent call last):
  File "uvloop/loop.pyx", line 1112, in uvloop.loop.Loop._create_server
  File "uvloop/handles/streamserver.pyx", line 58, in uvloop.loop.UVStreamServer.listen
  File "uvloop/handles/streamserver.pyx", line 95, in uvloop.loop.UVStreamServer._fatal_error
OSError: [Errno 98] Address already in use

During handling of the above exception, another exception occurred:

Traceback (most recent call last):
  File "/home/bartek/.local/lib/python3.6/site-packages/sanic/server.py", line 745, in serve
    http_server = loop.run_until_complete(server_coroutine)
  File "uvloop/loop.pyx", line 1451, in uvloop.loop.Loop.run_until_complete
  File "uvloop/loop.pyx", line 1684, in create_server
  File "uvloop/loop.pyx", line 1116, in uvloop.loop.Loop._create_server
OSError: [Errno 98] error while attempting to bind on address ('0.0.0.0', 5005): address already in use
2019-07-15 13:01:38,650 [ERROR]  Unable to start server
Traceback (most recent call last):
  File "uvloop/loop.pyx", line 1112, in uvloop.loop.Loop._create_server
  File "uvloop/handles/streamserver.pyx", line 58, in uvloop.loop.UVStreamServer.listen
  File "uvloop/handles/streamserver.pyx", line 95, in uvloop.loop.UVStreamServer._fatal_error
OSError: [Errno 98] Address already in use

During handling of the above exception, another exception occurred:

Traceback (most recent call last):
  File "/home/bartek/.local/lib/python3.6/site-packages/sanic/server.py", line 745, in serve
    http_server = loop.run_until_complete(server_coroutine)
  File "uvloop/loop.pyx", line 1451, in uvloop.loop.Loop.run_until_complete
  File "uvloop/loop.pyx", line 1684, in create_server
  File "uvloop/loop.pyx", line 1116, in uvloop.loop.Loop._create_server
OSError: [Errno 98] error while attempting to bind on address ('0.0.0.0', 5005): address already in use
2019-07-15 13:01:53,666 [ERROR]  Unable to start server
Traceback (most recent call last):
  File "uvloop/loop.pyx", line 1112, in uvloop.loop.Loop._create_server
  File "uvloop/handles/streamserver.pyx", line 58, in uvloop.loop.UVStreamServer.listen
  File "uvloop/handles/streamserver.pyx", line 95, in uvloop.loop.UVStreamServer._fatal_error
OSError: [Errno 98] Address already in use

During handling of the above exception, another exception occurred:

Traceback (most recent call last):
  File "/home/bartek/.local/lib/python3.6/site-packages/sanic/server.py", line 745, in serve
    http_server = loop.run_until_complete(server_coroutine)
  File "uvloop/loop.pyx", line 1451, in uvloop.loop.Loop.run_until_complete
  File "uvloop/loop.pyx", line 1684, in create_server
  File "uvloop/loop.pyx", line 1116, in uvloop.loop.Loop._create_server
OSError: [Errno 98] error while attempting to bind on address ('0.0.0.0', 5005): address already in use
2019-07-15 13:02:25,548 [ERROR]  Unable to start server
Traceback (most recent call last):
  File "uvloop/loop.pyx", line 1112, in uvloop.loop.Loop._create_server
  File "uvloop/handles/streamserver.pyx", line 58, in uvloop.loop.UVStreamServer.listen
  File "uvloop/handles/streamserver.pyx", line 95, in uvloop.loop.UVStreamServer._fatal_error
OSError: [Errno 98] Address already in use

During handling of the above exception, another exception occurred:

Traceback (most recent call last):
  File "/home/bartek/.local/lib/python3.6/site-packages/sanic/server.py", line 745, in serve
    http_server = loop.run_until_complete(server_coroutine)
  File "uvloop/loop.pyx", line 1451, in uvloop.loop.Loop.run_until_complete
  File "uvloop/loop.pyx", line 1684, in create_server
  File "uvloop/loop.pyx", line 1116, in uvloop.loop.Loop._create_server
OSError: [Errno 98] error while attempting to bind on address ('0.0.0.0', 5005): address already in use
2019-07-15 13:02:51,087 [ERROR]  Unable to start server
Traceback (most recent call last):
  File "uvloop/loop.pyx", line 1112, in uvloop.loop.Loop._create_server
  File "uvloop/handles/streamserver.pyx", line 58, in uvloop.loop.UVStreamServer.listen
  File "uvloop/handles/streamserver.pyx", line 95, in uvloop.loop.UVStreamServer._fatal_error
OSError: [Errno 98] Address already in use

During handling of the above exception, another exception occurred:

Traceback (most recent call last):
  File "/home/bartek/Enviroments/simple_rasa_bot/lib/python3.6/site-packages/sanic/server.py", line 745, in serve
    http_server = loop.run_until_complete(server_coroutine)
  File "uvloop/loop.pyx", line 1451, in uvloop.loop.Loop.run_until_complete
  File "uvloop/loop.pyx", line 1684, in create_server
  File "uvloop/loop.pyx", line 1116, in uvloop.loop.Loop._create_server
OSError: [Errno 98] error while attempting to bind on address ('0.0.0.0', 5005): address already in use
2019-07-15 13:03:57,766 [ERROR]  Unable to start server
Traceback (most recent call last):
  File "uvloop/loop.pyx", line 1112, in uvloop.loop.Loop._create_server
  File "uvloop/handles/streamserver.pyx", line 58, in uvloop.loop.UVStreamServer.listen
  File "uvloop/handles/streamserver.pyx", line 95, in uvloop.loop.UVStreamServer._fatal_error
OSError: [Errno 98] Address already in use

During handling of the above exception, another exception occurred:

Traceback (most recent call last):
  File "/home/bartek/.local/lib/python3.6/site-packages/sanic/server.py", line 745, in serve
    http_server = loop.run_until_complete(server_coroutine)
  File "uvloop/loop.pyx", line 1451, in uvloop.loop.Loop.run_until_complete
  File "uvloop/loop.pyx", line 1684, in create_server
  File "uvloop/loop.pyx", line 1116, in uvloop.loop.Loop._create_server
OSError: [Errno 98] error while attempting to bind on address ('0.0.0.0', 5005): address already in use
2019-07-15 13:04:13,855 [ERROR]  Unable to start server
Traceback (most recent call last):
  File "uvloop/loop.pyx", line 1112, in uvloop.loop.Loop._create_server
  File "uvloop/handles/streamserver.pyx", line 58, in uvloop.loop.UVStreamServer.listen
  File "uvloop/handles/streamserver.pyx", line 95, in uvloop.loop.UVStreamServer._fatal_error
OSError: [Errno 98] Address already in use

During handling of the above exception, another exception occurred:

Traceback (most recent call last):
  File "/home/bartek/.local/lib/python3.6/site-packages/sanic/server.py", line 745, in serve
    http_server = loop.run_until_complete(server_coroutine)
  File "uvloop/loop.pyx", line 1451, in uvloop.loop.Loop.run_until_complete
  File "uvloop/loop.pyx", line 1684, in create_server
  File "uvloop/loop.pyx", line 1116, in uvloop.loop.Loop._create_server
OSError: [Errno 98] error while attempting to bind on address ('0.0.0.0', 5005): address already in use
2019-07-15 14:06:52,023 [ERROR]  Exception occurred while handling uri: 'http://ce516bed.ngrok.io/webhooks/slack/webhok'
Traceback (most recent call last):
  File "/home/bartek/.local/lib/python3.6/site-packages/sanic/app.py", line 893, in handle_request
    handler, args, kwargs, uri = self.router.get(request)
  File "/home/bartek/.local/lib/python3.6/site-packages/sanic/router.py", line 407, in get
    return self._get(request.path, request.method, "")
  File "/home/bartek/.local/lib/python3.6/site-packages/sanic/router.py", line 469, in _get
    raise NotFound("Requested URL {} not found".format(url))
sanic.exceptions.NotFound: Requested URL /webhooks/slack/webhok not found
2019-07-15 14:06:57,308 [ERROR]  Exception occurred while handling uri: 'http://ce516bed.ngrok.io/webhooks/slack/webhok'
Traceback (most recent call last):
  File "/home/bartek/.local/lib/python3.6/site-packages/sanic/app.py", line 893, in handle_request
    handler, args, kwargs, uri = self.router.get(request)
  File "/home/bartek/.local/lib/python3.6/site-packages/sanic/router.py", line 407, in get
    return self._get(request.path, request.method, "")
  File "/home/bartek/.local/lib/python3.6/site-packages/sanic/router.py", line 469, in _get
    raise NotFound("Requested URL {} not found".format(url))
sanic.exceptions.NotFound: Requested URL /webhooks/slack/webhok not found
2019-07-15 14:07:03,965 [ERROR]  Exception occurred while handling uri: 'http://ce516bed.ngrok.io/webhooks/slack/webhok'
Traceback (most recent call last):
  File "/home/bartek/.local/lib/python3.6/site-packages/sanic/app.py", line 893, in handle_request
    handler, args, kwargs, uri = self.router.get(request)
  File "/home/bartek/.local/lib/python3.6/site-packages/sanic/router.py", line 407, in get
    return self._get(request.path, request.method, "")
  File "/home/bartek/.local/lib/python3.6/site-packages/sanic/router.py", line 469, in _get
    raise NotFound("Requested URL {} not found".format(url))
sanic.exceptions.NotFound: Requested URL /webhooks/slack/webhok not found
2019-07-15 17:03:04,944 [DEBUG]  Available web server routes: 
/webhooks/slack                                    GET                            slack_webhook.health
/webhooks/slack/webhook                            GET                            slack_webhook.webhook
2019-07-16 15:29:08,212 [ERROR]  Unable to start server
Traceback (most recent call last):
  File "uvloop/loop.pyx", line 1112, in uvloop.loop.Loop._create_server
  File "uvloop/handles/streamserver.pyx", line 58, in uvloop.loop.UVStreamServer.listen
  File "uvloop/handles/streamserver.pyx", line 95, in uvloop.loop.UVStreamServer._fatal_error
OSError: [Errno 98] Address already in use

During handling of the above exception, another exception occurred:

Traceback (most recent call last):
  File "/home/bartek/.local/lib/python3.6/site-packages/sanic/server.py", line 745, in serve
    http_server = loop.run_until_complete(server_coroutine)
  File "uvloop/loop.pyx", line 1451, in uvloop.loop.Loop.run_until_complete
  File "uvloop/loop.pyx", line 1684, in create_server
  File "uvloop/loop.pyx", line 1116, in uvloop.loop.Loop._create_server
OSError: [Errno 98] error while attempting to bind on address ('0.0.0.0', 5005): address already in use
2019-07-16 15:29:24,903 [ERROR]  Unable to start server
Traceback (most recent call last):
  File "uvloop/loop.pyx", line 1112, in uvloop.loop.Loop._create_server
  File "uvloop/handles/streamserver.pyx", line 58, in uvloop.loop.UVStreamServer.listen
  File "uvloop/handles/streamserver.pyx", line 95, in uvloop.loop.UVStreamServer._fatal_error
OSError: [Errno 98] Address already in use

During handling of the above exception, another exception occurred:

Traceback (most recent call last):
  File "/home/bartek/.local/lib/python3.6/site-packages/sanic/server.py", line 745, in serve
    http_server = loop.run_until_complete(server_coroutine)
  File "uvloop/loop.pyx", line 1451, in uvloop.loop.Loop.run_until_complete
  File "uvloop/loop.pyx", line 1684, in create_server
  File "uvloop/loop.pyx", line 1116, in uvloop.loop.Loop._create_server
OSError: [Errno 98] error while attempting to bind on address ('0.0.0.0', 5005): address already in use
2019-07-16 15:29:58,320 [ERROR]  Unable to start server
Traceback (most recent call last):
  File "uvloop/loop.pyx", line 1112, in uvloop.loop.Loop._create_server
  File "uvloop/handles/streamserver.pyx", line 58, in uvloop.loop.UVStreamServer.listen
  File "uvloop/handles/streamserver.pyx", line 95, in uvloop.loop.UVStreamServer._fatal_error
OSError: [Errno 98] Address already in use

During handling of the above exception, another exception occurred:

Traceback (most recent call last):
  File "/home/bartek/.local/lib/python3.6/site-packages/sanic/server.py", line 745, in serve
    http_server = loop.run_until_complete(server_coroutine)
  File "uvloop/loop.pyx", line 1451, in uvloop.loop.Loop.run_until_complete
  File "uvloop/loop.pyx", line 1684, in create_server
  File "uvloop/loop.pyx", line 1116, in uvloop.loop.Loop._create_server
OSError: [Errno 98] error while attempting to bind on address ('0.0.0.0', 5005): address already in use
2019-07-16 15:30:29,361 [ERROR]  Unable to start server
Traceback (most recent call last):
  File "uvloop/loop.pyx", line 1112, in uvloop.loop.Loop._create_server
  File "uvloop/handles/streamserver.pyx", line 58, in uvloop.loop.UVStreamServer.listen
  File "uvloop/handles/streamserver.pyx", line 95, in uvloop.loop.UVStreamServer._fatal_error
OSError: [Errno 98] Address already in use

During handling of the above exception, another exception occurred:

Traceback (most recent call last):
  File "/home/bartek/Enviroments/simple_rasa_bot/lib/python3.6/site-packages/sanic/server.py", line 745, in serve
    http_server = loop.run_until_complete(server_coroutine)
  File "uvloop/loop.pyx", line 1451, in uvloop.loop.Loop.run_until_complete
  File "uvloop/loop.pyx", line 1684, in create_server
  File "uvloop/loop.pyx", line 1116, in uvloop.loop.Loop._create_server
OSError: [Errno 98] error while attempting to bind on address ('0.0.0.0', 5005): address already in use
